#VRML_SIM R2025a utf8
# license: Apache License 2.0
# license url: http://www.apache.org/licenses/LICENSE-2.0
# This is a proto file for Webots for the robot
# Extracted from: /Users/coleaskey/ros2_ws/src/robot/urdf/robot.urdf

PROTO robot [
  field  SFVec3f     translation     0 0 0
  field  SFRotation  rotation        0 0 1 0
  field  SFString    name            "robot"  # Is `Robot.name`.
  field  SFString    controller      "void"   # Is `Robot.controller`.
  field  MFString    controllerArgs  []       # Is `Robot.controllerArgs`.
  field  SFString    customData      ""       # Is `Robot.customData`.
  field  SFBool      supervisor      FALSE    # Is `Robot.supervisor`.
  field  SFBool      synchronization TRUE     # Is `Robot.synchronization`.
  field  SFBool      selfCollision   FALSE    # Is `Robot.selfCollision`.
]
{
  Robot {
    translation IS translation
    rotation IS rotation
    controller IS controller
    controllerArgs IS controllerArgs
    customData IS customData
    supervisor IS supervisor
    synchronization IS synchronization
    selfCollision IS selfCollision
    children [
      Shape {
        appearance DEF blue PBRAppearance {
          baseColor 0.200000 0.400000 0.800000
          roughness 1.000000
          metalness 0
        }
        geometry Box {
           size 0.400000 0.300000 0.100000
        }
      }
      HingeJoint {
        jointParameters HingeJointParameters {
          axis 0.000000 -1.000000 -0.000004
          anchor 0.150000 0.200000 0.000000
        }
        device [
          RotationalMotor {
            name "front_left_wheel"
            maxTorque 10000
          }
          PositionSensor {
            name "front_left_wheel_sensor"
          }
        ]
        endPoint Solid {
          translation 0.150000 0.200000 0.000000
          rotation 1.000000 0.000000 0.000000 1.570800
          children [
            Shape {
              appearance DEF black PBRAppearance {
                baseColor 0.100000 0.100000 0.100000
                roughness 1.000000
                metalness 0
              }
              geometry Cylinder {
                radius 0.08
                height 0.05
              }
            }
          ]
          name "front_left_wheel_link"
          boundingObject Cylinder {
            radius 0.08
            height 0.05
          }
          physics Physics {
            density -1
            mass 0.500000
            centerOfMass [ 0.000000 0.000000 0.000000 ]
            inertiaMatrix [
              1.000000e-02 1.000000e-02 1.000000e-02
              0.000000e+00 0.000000e+00 0.000000e+00
            ]
          }
        }
      }
      HingeJoint {
        jointParameters HingeJointParameters {
          axis 0.000000 -1.000000 -0.000004
          anchor 0.150000 -0.200000 0.000000
        }
        device [
          RotationalMotor {
            name "front_right_wheel"
            maxTorque 10000
          }
          PositionSensor {
            name "front_right_wheel_sensor"
          }
        ]
        endPoint Solid {
          translation 0.150000 -0.200000 0.000000
          rotation 1.000000 0.000000 0.000000 1.570800
          children [
            Shape {
              appearance USE black
              geometry Cylinder {
                radius 0.08
                height 0.05
              }
            }
          ]
          name "front_right_wheel_link"
          boundingObject Cylinder {
            radius 0.08
            height 0.05
          }
          physics Physics {
            density -1
            mass 0.500000
            centerOfMass [ 0.000000 0.000000 0.000000 ]
            inertiaMatrix [
              1.000000e-02 1.000000e-02 1.000000e-02
              0.000000e+00 0.000000e+00 0.000000e+00
            ]
          }
        }
      }
      HingeJoint {
        jointParameters HingeJointParameters {
          axis 0.000000 -1.000000 -0.000004
          anchor -0.150000 0.200000 0.000000
        }
        device [
          RotationalMotor {
            name "rear_left_wheel"
            maxTorque 10000
          }
          PositionSensor {
            name "rear_left_wheel_sensor"
          }
        ]
        endPoint Solid {
          translation -0.150000 0.200000 0.000000
          rotation 1.000000 0.000000 0.000000 1.570800
          children [
            Shape {
              appearance USE black
              geometry Cylinder {
                radius 0.08
                height 0.05
              }
            }
          ]
          name "rear_left_wheel_link"
          boundingObject Cylinder {
            radius 0.08
            height 0.05
          }
          physics Physics {
            density -1
            mass 0.500000
            centerOfMass [ 0.000000 0.000000 0.000000 ]
            inertiaMatrix [
              1.000000e-02 1.000000e-02 1.000000e-02
              0.000000e+00 0.000000e+00 0.000000e+00
            ]
          }
        }
      }
      HingeJoint {
        jointParameters HingeJointParameters {
          axis 0.000000 -1.000000 -0.000004
          anchor -0.150000 -0.200000 0.000000
        }
        device [
          RotationalMotor {
            name "rear_right_wheel"
            maxTorque 10000
          }
          PositionSensor {
            name "rear_right_wheel_sensor"
          }
        ]
        endPoint Solid {
          translation -0.150000 -0.200000 0.000000
          rotation 1.000000 0.000000 0.000000 1.570800
          children [
            Shape {
              appearance USE black
              geometry Cylinder {
                radius 0.08
                height 0.05
              }
            }
          ]
          name "rear_right_wheel_link"
          boundingObject Cylinder {
            radius 0.08
            height 0.05
          }
          physics Physics {
            density -1
            mass 0.500000
            centerOfMass [ 0.000000 0.000000 0.000000 ]
            inertiaMatrix [
              1.000000e-02 1.000000e-02 1.000000e-02
              0.000000e+00 0.000000e+00 0.000000e+00
            ]
          }
        }
      }
      HingeJoint {
        jointParameters HingeJointParameters {
          axis 0.000000 0.000000 1.000000
          anchor 0.000000 0.000000 0.050000
          dampingConstant 1.0
        }
        device [
          RotationalMotor {
            name "arm_joint_1"
            maxVelocity 3.15
            minPosition -6.28
            maxPosition 6.28
            maxTorque 100.0
          }
          PositionSensor {
            name "arm_joint_1_sensor"
          }
        ]
        endPoint Solid {
          translation 0.000000 0.000000 0.050000
          children [
            Pose {
              translation 0.000000 0.000000 0.060000
              children [
                Shape {
                  appearance DEF dark_gray PBRAppearance {
                    baseColor 0.150000 0.150000 0.200000
                    roughness 1.000000
                    metalness 0
                  }
                  geometry Cylinder {
                    radius 0.075
                    height 0.12
                  }
                }
              ]
            }
            HingeJoint {
              jointParameters HingeJointParameters {
                axis 0.000000 1.000000 0.000000
                anchor 0.000000 0.000000 0.060000
                dampingConstant 1.0
              }
              device [
                RotationalMotor {
                  name "arm_joint_2"
                  maxVelocity 3.15
                  minPosition -3.14
                  maxPosition 3.14
                  maxTorque 100.0
                }
                PositionSensor {
                  name "arm_joint_2_sensor"
                }
              ]
              endPoint Solid {
                translation 0.000000 0.000000 0.060000
                children [
                  Pose {
                    translation 0.000000 0.000000 0.200000
                    children [
                      Shape {
                        appearance DEF arm_blue PBRAppearance {
                          baseColor 0.200000 0.350000 0.550000
                          roughness 1.000000
                          metalness 0
                        }
                        geometry Box {
                           size 0.080000 0.080000 0.350000
                        }
                      }
                    ]
                  }
                  HingeJoint {
                    jointParameters HingeJointParameters {
                      axis 0.000000 1.000000 0.000000
                      anchor 0.000000 0.000000 0.375000
                      dampingConstant 1.0
                    }
                    device [
                      RotationalMotor {
                        name "arm_joint_3"
                        maxVelocity 3.15
                        minPosition -3.14
                        maxPosition 3.14
                        maxTorque 100.0
                      }
                      PositionSensor {
                        name "arm_joint_3_sensor"
                      }
                    ]
                    endPoint Solid {
                      translation 0.000000 0.000000 0.375000
                      children [
                        Pose {
                          translation 0.000000 0.000000 0.150000
                          children [
                            Shape {
                              appearance USE arm_blue
                              geometry Box {
                                 size 0.070000 0.070000 0.270000
                              }
                            }
                          ]
                        }
                        HingeJoint {
                          jointParameters HingeJointParameters {
                            axis 0.000000 0.000000 1.000000
                            anchor 0.000000 0.000000 0.285000
                            dampingConstant 1.0
                          }
                          device [
                            RotationalMotor {
                              name "arm_joint_4"
                              maxVelocity 3.2
                              minPosition -6.28
                              maxPosition 6.28
                              maxTorque 50.0
                            }
                            PositionSensor {
                              name "arm_joint_4_sensor"
                            }
                          ]
                          endPoint Solid {
                            translation 0.000000 0.000000 0.285000
                            children [
                              Pose {
                                translation 0.000000 0.000000 0.050000
                                children [
                                  Shape {
                                    appearance DEF wrist_gray PBRAppearance {
                                      baseColor 0.180000 0.180000 0.220000
                                      roughness 1.000000
                                      metalness 0
                                    }
                                    geometry Cylinder {
                                      radius 0.03
                                      height 0.1
                                    }
                                  }
                                ]
                              }
                              HingeJoint {
                                jointParameters HingeJointParameters {
                                  axis 0.000000 1.000000 0.000000
                                  anchor 0.000000 0.000000 0.050000
                                  dampingConstant 1.0
                                }
                                device [
                                  RotationalMotor {
                                    name "arm_joint_5"
                                    maxVelocity 3.2
                                    minPosition -6.28
                                    maxPosition 6.28
                                    maxTorque 50.0
                                  }
                                  PositionSensor {
                                    name "arm_joint_5_sensor"
                                  }
                                ]
                                endPoint Solid {
                                  translation 0.000000 0.000000 0.050000
                                  children [
                                    Pose {
                                      translation 0.000000 0.000000 0.020000
                                      children [
                                        Shape {
                                          appearance DEF wrist_light_gray PBRAppearance {
                                            baseColor 0.250000 0.250000 0.300000
                                            roughness 1.000000
                                            metalness 0
                                          }
                                          geometry Cylinder {
                                            radius 0.04
                                            height 0.04
                                          }
                                        }
                                      ]
                                    }
                                    HingeJoint {
                                      jointParameters HingeJointParameters {
                                        axis 0.000000 0.000000 1.000000
                                        anchor 0.000000 0.000000 0.020000
                                        dampingConstant 1.0
                                      }
                                      device [
                                        RotationalMotor {
                                          name "arm_joint_6"
                                          maxVelocity 3.2
                                          minPosition -6.28
                                          maxPosition 6.28
                                          maxTorque 50.0
                                        }
                                        PositionSensor {
                                          name "arm_joint_6_sensor"
                                        }
                                      ]
                                      endPoint Solid {
                                        translation 0.000000 0.000000 0.020000
                                        children [
                                          Pose {
                                            translation 0.000000 0.000000 0.012500
                                            children [
                                              Shape {
                                                appearance DEF tool_flange PBRAppearance {
                                                  baseColor 0.150000 0.150000 0.180000
                                                  roughness 1.000000
                                                  metalness 0
                                                }
                                                geometry Cylinder {
                                                  radius 0.035
                                                  height 0.025
                                                }
                                              }
                                            ]
                                          }
                                          Solid {
                                            translation 0.000000 0.000000 0.025000
                                            children [
                                              Pose {
                                                translation 0.000000 0.000000 0.030000
                                                children [
                                                  Shape {
                                                    appearance DEF gripper PBRAppearance {
                                                      baseColor 0.100000 0.100000 0.120000
                                                      roughness 1.000000
                                                      metalness 0
                                                    }
                                                    geometry Box {
                                                       size 0.050000 0.040000 0.060000
                                                    }
                                                  }
                                                ]
                                              }
                                            ]
                                            name "tool0"
                                            boundingObject Pose {
                                              translation 0.000000 0.000000 0.030000
                                              children [
                                                Box {
                                                   size 0.050000 0.040000 0.060000
                                                }
                                              ]
                                            }
                                            physics Physics {
                                              density -1
                                              mass 0.100000
                                              centerOfMass [ 0.000000 0.000000 0.030000 ]
                                              inertiaMatrix [
                                                1.000000e-04 1.000000e-04 1.000000e-04
                                                0.000000e+00 0.000000e+00 0.000000e+00
                                              ]
                                            }
                                          }
                                        ]
                                        name "wrist_3_link"
                                        boundingObject Pose {
                                          translation 0.000000 0.000000 0.012500
                                          children [
                                            Cylinder {
                                              radius 0.035
                                              height 0.025
                                            }
                                          ]
                                        }
                                        physics Physics {
                                          density -1
                                          mass 0.150000
                                          centerOfMass [ 0.000000 0.000000 0.012500 ]
                                          inertiaMatrix [
                                            5.000000e-04 5.000000e-04 5.000000e-04
                                            0.000000e+00 0.000000e+00 0.000000e+00
                                          ]
                                        }
                                      }
                                    }
                                  ]
                                  name "wrist_2_link"
                                  boundingObject Pose {
                                    translation 0.000000 0.000000 0.020000
                                    children [
                                      Cylinder {
                                        radius 0.04
                                        height 0.04
                                      }
                                    ]
                                  }
                                  physics Physics {
                                    density -1
                                    mass 0.200000
                                    centerOfMass [ 0.000000 0.000000 0.020000 ]
                                    inertiaMatrix [
                                      1.000000e-03 1.000000e-03 1.000000e-03
                                      0.000000e+00 0.000000e+00 0.000000e+00
                                    ]
                                  }
                                }
                              }
                            ]
                            name "wrist_1_link"
                            boundingObject Pose {
                              translation 0.000000 0.000000 0.050000
                              children [
                                Cylinder {
                                  radius 0.03
                                  height 0.1
                                }
                              ]
                            }
                            physics Physics {
                              density -1
                              mass 0.300000
                              centerOfMass [ 0.000000 0.000000 0.050000 ]
                              inertiaMatrix [
                                1.000000e-03 1.000000e-03 1.000000e-03
                                0.000000e+00 0.000000e+00 0.000000e+00
                              ]
                            }
                          }
                        }
                      ]
                      name "elbow_link"
                      boundingObject Pose {
                        translation 0.000000 0.000000 0.150000
                        children [
                          Box {
                             size 0.070000 0.070000 0.270000
                          }
                        ]
                      }
                      physics Physics {
                        density -1
                        mass 1.200000
                        centerOfMass [ 0.000000 0.000000 0.150000 ]
                        inertiaMatrix [
                          1.000000e-02 1.000000e-02 5.000000e-03
                          0.000000e+00 0.000000e+00 0.000000e+00
                        ]
                      }
                    }
                  }
                ]
                name "shoulder_link"
                boundingObject Pose {
                  translation 0.000000 0.000000 0.200000
                  children [
                    Box {
                       size 0.080000 0.080000 0.350000
                    }
                  ]
                }
                physics Physics {
                  density -1
                  mass 1.800000
                  centerOfMass [ 0.000000 0.000000 0.200000 ]
                  inertiaMatrix [
                    2.000000e-02 2.000000e-02 1.000000e-02
                    0.000000e+00 0.000000e+00 0.000000e+00
                  ]
                }
              }
            }
          ]
          name "arm_base_link"
          boundingObject Pose {
            translation 0.000000 0.000000 0.060000
            children [
              Cylinder {
                radius 0.075
                height 0.12
              }
            ]
          }
          physics Physics {
            density -1
            mass 1.500000
            centerOfMass [ 0.000000 0.000000 0.060000 ]
            inertiaMatrix [
              1.000000e-02 1.000000e-02 1.000000e-02
              0.000000e+00 0.000000e+00 0.000000e+00
            ]
          }
        }
      }
    ]
    name IS name
    boundingObject Box {
       size 0.400000 0.300000 0.100000
    }
    physics Physics {
      density -1
      mass 5.000000
      centerOfMass [ 0.000000 0.000000 0.000000 ]
      inertiaMatrix [
        1.000000e-01 1.000000e-01 1.000000e-01
        0.000000e+00 0.000000e+00 0.000000e+00
      ]
    }
  }
}
